Watching for file changes with StatReloader
Exception in thread django-main-thread:
Traceback (most recent call last):
  File "C:\Users\Surajderichard\AppData\Local\Programs\Python\Python38\lib\threading.py", line 932, in _bootstrap_inner
    self.run()
  File "C:\Users\Surajderichard\AppData\Local\Programs\Python\Python38\lib\threading.py", line 870, in run
    self._target(*self._args, **self._kwargs)
  File "C:\Users\Surajderichard\AppData\Local\Programs\Python\Python38\lib\site-packages\django\utils\autoreload.py", line 64, in wrapper
    fn(*args, **kwargs)
  File "C:\Users\Surajderichard\AppData\Local\Programs\Python\Python38\lib\site-packages\django\core\management\commands\runserver.py", line 115, in inner_run
    autoreload.raise_last_exception()
  File "C:\Users\Surajderichard\AppData\Local\Programs\Python\Python38\lib\site-packages\django\utils\autoreload.py", line 87, in raise_last_exception
    raise _exception[1]
  File "C:\Users\Surajderichard\AppData\Local\Programs\Python\Python38\lib\site-packages\django\core\management\__init__.py", line 381, in execute
    autoreload.check_errors(django.setup)()
  File "C:\Users\Surajderichard\AppData\Local\Programs\Python\Python38\lib\site-packages\django\utils\autoreload.py", line 64, in wrapper
    fn(*args, **kwargs)
  File "C:\Users\Surajderichard\AppData\Local\Programs\Python\Python38\lib\site-packages\django\__init__.py", line 24, in setup
    apps.populate(settings.INSTALLED_APPS)
  File "C:\Users\Surajderichard\AppData\Local\Programs\Python\Python38\lib\site-packages\django\apps\registry.py", line 91, in populate
    app_config = AppConfig.create(entry)
  File "C:\Users\Surajderichard\AppData\Local\Programs\Python\Python38\lib\site-packages\django\apps\config.py", line 223, in create
    import_module(entry)
  File "C:\Users\Surajderichard\AppData\Local\Programs\Python\Python38\lib\importlib\__init__.py", line 127, in import_module
    return _bootstrap._gcd_import(name[level:], package, level)
  File "<frozen importlib._bootstrap>", line 1014, in _gcd_import
  File "<frozen importlib._bootstrap>", line 991, in _find_and_load
  File "<frozen importlib._bootstrap>", line 973, in _find_and_load_unlocked
ModuleNotFoundError: No module named 'myapp'
Traceback (most recent call last):
  File "manage.py", line 22, in <module>
    main()
  File "manage.py", line 18, in main
    execute_from_command_line(sys.argv)
  File "C:\Users\Surajderichard\AppData\Local\Programs\Python\Python38\lib\site-packages\django\core\management\__init__.py", line 425, in execute_from_command_line
    utility.execute()
  File "C:\Users\Surajderichard\AppData\Local\Programs\Python\Python38\lib\site-packages\django\core\management\__init__.py", line 419, in execute
    self.fetch_command(subcommand).run_from_argv(self.argv)
  File "C:\Users\Surajderichard\AppData\Local\Programs\Python\Python38\lib\site-packages\django\core\management\base.py", line 373, in run_from_argv
    self.execute(*args, **cmd_options)
  File "C:\Users\Surajderichard\AppData\Local\Programs\Python\Python38\lib\site-packages\django\core\management\commands\runserver.py", line 66, in execute
    super().execute(*args, **options)
  File "C:\Users\Surajderichard\AppData\Local\Programs\Python\Python38\lib\site-packages\django\core\management\base.py", line 417, in execute
    output = self.handle(*args, **options)
  File "C:\Users\Surajderichard\AppData\Local\Programs\Python\Python38\lib\site-packages\django\core\management\commands\runserver.py", line 101, in handle
    self.run(**options)
  File "C:\Users\Surajderichard\AppData\Local\Programs\Python\Python38\lib\site-packages\django\core\management\commands\runserver.py", line 108, in run
    autoreload.run_with_reloader(self.inner_run, **options)
  File "C:\Users\Surajderichard\AppData\Local\Programs\Python\Python38\lib\site-packages\django\utils\autoreload.py", line 644, in run_with_reloader
    start_django(reloader, main_func, *args, **kwargs)
  File "C:\Users\Surajderichard\AppData\Local\Programs\Python\Python38\lib\site-packages\django\utils\autoreload.py", line 629, in start_django
    reloader.run(django_main_thread)
  File "C:\Users\Surajderichard\AppData\Local\Programs\Python\Python38\lib\site-packages\django\utils\autoreload.py", line 335, in run
    self.run_loop()
  File "C:\Users\Surajderichard\AppData\Local\Programs\Python\Python38\lib\site-packages\django\utils\autoreload.py", line 341, in run_loop
    next(ticker)
  File "C:\Users\Surajderichard\AppData\Local\Programs\Python\Python38\lib\site-packages\django\utils\autoreload.py", line 381, in tick
    for filepath, mtime in self.snapshot_files():
  File "C:\Users\Surajderichard\AppData\Local\Programs\Python\Python38\lib\site-packages\django\utils\autoreload.py", line 397, in snapshot_files
    for file in self.watched_files():
  File "C:\Users\Surajderichard\AppData\Local\Programs\Python\Python38\lib\site-packages\django\utils\autoreload.py", line 295, in watched_files
    yield from iter_all_python_module_files()
  File "C:\Users\Surajderichard\AppData\Local\Programs\Python\Python38\lib\site-packages\django\utils\autoreload.py", line 116, in iter_all_python_module_files
    return iter_modules_and_files(modules, frozenset(_error_files))
  File "C:\Users\Surajderichard\AppData\Local\Programs\Python\Python38\lib\site-packages\django\utils\autoreload.py", line 152, in iter_modules_and_files
    if not path.exists():
  File "C:\Users\Surajderichard\AppData\Local\Programs\Python\Python38\lib\pathlib.py", line 1388, in exists
    self.stat()
  File "C:\Users\Surajderichard\AppData\Local\Programs\Python\Python38\lib\pathlib.py", line 1194, in stat
    return self._accessor.stat(self)
OSError: [WinError 123] The filename, directory name, or volume label syntax is incorrect: '<frozen importlib._bootstrap>'
